<robot
  name="2015_drawer_urdf_3a">
  <link
    name="base_link">
    <visual>
      <origin
        xyz="0 0 0"
        rpy="0 0 0" />
      <geometry>
        <mesh
          filename="package://2015_drawer_urdf_3a/meshes/base_link.STL" />
      </geometry>
      <material
        name="">
        <color
          rgba="0.792156862745098 0.819607843137255 0.933333333333333 1" />
      </material>
    </visual>
    <collision>
      <origin
        xyz="0 0 0"
        rpy="0 0 0" />
      <geometry>
        <mesh
          filename="package://2015_drawer_urdf_3a/meshes/base_link.STL" />
      </geometry>
    </collision>
  </link>
  <link
    name="Rotation_link">
    <visual>
      <origin
        xyz="0 0 0"
        rpy="0 0 0" />
      <geometry>
        <mesh
          filename="package://2015_drawer_urdf_3a/meshes/Rotation_link.STL" />
      </geometry>
      <material
        name="">
        <color
          rgba="0.792156862745098 0.819607843137255 0.933333333333333 1" />
      </material>
    </visual>
    <collision>
      <origin
        xyz="0 0 0"
        rpy="0 0 0" />
      <geometry>
        <mesh
          filename="package://2015_drawer_urdf_3a/meshes/Rotation_link.STL" />
      </geometry>
    </collision>
  </link>
  <joint
    name="Rotation_link"
    type="revolute">
    <origin
      xyz="0 0 0"
      rpy="0 0 0" />
    <parent
      link="base_link" />
    <child
      link="Rotation_link" />
    <axis
      xyz="0 0 1" />
    <limit
      lower="-3.14159"
      upper="3.14159"
      effort="0"
      velocity="0" />
  </joint>
  <link
    name="Translation_link">
    <visual>
      <origin
        xyz="0 0 0"
        rpy="0 0 0" />
      <geometry>
        <mesh
          filename="package://2015_drawer_urdf_3a/meshes/Translation_link.STL" />
      </geometry>
      <material
        name="">
        <color
          rgba="0.752941176470588 0.752941176470588 0.752941176470588 1" />
      </material>
    </visual>
    <collision>
      <origin
        xyz="0 0 0"
        rpy="0 0 0" />
      <geometry>
        <mesh
          filename="package://2015_drawer_urdf_3a/meshes/Translation_link.STL" />
      </geometry>
    </collision>
  </link>
  <joint
    name="Translation_link"
    type="prismatic">
    <origin
      xyz="0 0 0"
      rpy="0 0 0" />
    <parent
      link="Rotation_link" />
    <child
      link="Translation_link" />
    <axis
      xyz="1 0 0" />
    <limit
      lower="-0.2"
      upper="0"
      effort="0"
      velocity="0" />
  </joint>
  <link
    name="dummy_link">
    <visual>
      <origin
        xyz="0 0 0"
        rpy="0 0 0" />
      <geometry>
        <mesh
          filename="package://2015_drawer_urdf_3a/meshes/dummy_link.STL" />
      </geometry>
      <material
        name="">
        <color
          rgba="0.792156862745098 0.819607843137255 0.933333333333333 1" />
      </material>
    </visual>
    <collision>
      <origin
        xyz="0 0 0"
        rpy="0 0 0" />
      <geometry>
        <mesh
          filename="package://2015_drawer_urdf_3a/meshes/dummy_link.STL" />
      </geometry>
    </collision>
  </link>
  <joint
    name="dummy_link"
    type="revolute">
    <origin
      xyz="-0.192576 0.0063436 0.11251"
      rpy="0 0 1.571" />
    <parent
      link="Translation_link" />
    <child
      link="dummy_link" />
    <axis
      xyz="0 1 0" />
    <limit
      lower="0"
      upper="0"
      effort="0"
      velocity="0" />
  </joint>
</robot>
