<robot
  name="V1.5_Arm_URDF">

  <link
    name="V1pt5_base_link">
    <inertial>
      <origin
        xyz="-0.00055124  -0.02427719 -0.02322142"
        rpy="0 0 0" />
      <mass
        value="1.9" />
      <inertia
        ixx="0.00758967"
        ixy="0.00001624"
        ixz="0.00002591"
        iyy="0.00439493"
        iyz="0.00281287"
        izz="0.00472741" />
    </inertial>
    <visual>
      <origin
        xyz="0 0 0"
        rpy="0 0 0" />
      <geometry>
        <mesh
          filename="package://V1pt5_Arm_URDF/meshes/V1pt5_base_link.STL" />
      </geometry>
      <material
        name="">
        <color
          rgba="0.75294 0.75294 0.75294 1" />
      </material>
    </visual>
    <collision>
      <origin
        xyz="0 0 0"
        rpy="0 0 0" />
      <geometry>
        <mesh
          filename="package://V1pt5_Arm_URDF/meshes/V1pt5_base_link.STL" />
      </geometry>
    </collision>
  </link>

<link
    name="V1pt5_shoulder_pitch_link">
    <inertial>
      <origin
        xyz="0.06218887 0 0.00000160"
        rpy="0 0 0" />
      <mass
        value="1.195" />
      <inertia
        ixx="0.00183098"
        ixy="0"
        ixz="0.00000007"
        iyy="0.00350504"
        iyz="0"
        izz="0.00256228" />
    </inertial>
    <visual>
      <origin
        xyz="0 0 0"
        rpy="0 0 0" />
      <geometry>
        <mesh
          filename="package://V1pt5_Arm_URDF/meshes/V1pt5_shoulder_pitch_link.STL" />
      </geometry>
      <material
        name="">
        <color
          rgba="0.6 0.72549 1 1" />
      </material>
    </visual>
    <collision>
      <origin
        xyz="0 0 0"
        rpy="0 0 0" />
      <geometry>
        <mesh
          filename="package://V1pt5_Arm_URDF/meshes/V1pt5_shoulder_pitch_link.STL" />
      </geometry>
    </collision>
  </link>

<joint
    name="V1pt5_shoulder_pitch_joint"
    type="revolute">
    <origin
      xyz="0 0 0"
      rpy="-1.5708 0.4712 -1.5708" />
    <parent
      link="V1pt5_base_link" />
    <child
      link="V1pt5_shoulder_pitch_link" />
    <axis
      xyz="0 0 1" />
    <limit effort="30" lower="-2.3607" upper=".7809" velocity="1.0"/>
  </joint>

<link
    name="V1pt5_shoulder_roll_link">
    <inertial>
      <origin
        xyz="0.01458174 -0.00413297 -0.02515561"
        rpy="0 0 0" />
      <mass
        value="1.11009836" />
      <inertia
        ixx="0.00401768"
        ixy="-0.00002444"
        ixz="0.00040343"
        iyy="0.00409481"
        iyz="-0.00011996"
        izz="0.00088051" />
    </inertial>
    <visual>
      <origin
        xyz="0 0 0"
        rpy="0 0 0" />
      <geometry>
        <mesh
          filename="package://V1pt5_Arm_URDF/meshes/V1pt5_shoulder_roll_link.STL" />
      </geometry>
      <material
        name="">
        <color
          rgba="1 0.75686 0.38431 1" />
      </material>
    </visual>
    <collision>
      <origin
        xyz="0 0 0"
        rpy="0 0 0" />
      <geometry>
        <mesh
          filename="package://V1pt5_Arm_URDF/meshes/V1pt5_shoulder_roll_link.STL" />
      </geometry>
    </collision>
  </link>

<joint
    name="V1pt5_shoulder_roll_joint"
    type="revolute">
    <origin
      xyz="0.07765 0.28958 0"
      rpy="-1.5708 0 0" />
    <parent
      link="V1pt5_shoulder_pitch_link" />
    <child
      link="V1pt5_shoulder_roll_link" />
    <axis
      xyz="0 0 1" />
    <limit effort="30" lower="-1.5708" upper="1.5708" velocity="1.0"/>
  </joint>

<link
    name="V1pt5_elbow_link">
    <inertial>
      <origin
        xyz="0.02404932 0.06734925 -0.02975223"
        rpy="0 0 0" />
      <mass
        value="1.281" />
      <inertia
        ixx="0.00269566"
        ixy="0.00050162"
        ixz="0.00013679"
        iyy="0.00112075"
        iyz="0.00055297"
        izz="0.00279944" />
    </inertial>
    <visual>
      <origin
        xyz="0 0 0"
        rpy="0 0 0" />
      <geometry>
        <mesh
          filename="package://V1pt5_Arm_URDF/meshes/V1pt5_elbow_link.STL" />
      </geometry>
      <material
        name="">
        <color
          rgba="0.61569 1 0.55294 1" />
      </material>
    </visual>
    <collision>
      <origin
        xyz="0 0 0"
        rpy="0 0 0" />
      <geometry>
        <mesh
          filename="package://V1pt5_Arm_URDF/meshes/V1pt5_elbow_link.STL" />
      </geometry>
    </collision>
  </link>

<joint
    name="V1pt5_elbow_joint"
    type="revolute">
    <origin
      xyz="0 0 0"
      rpy="-1.5708 -0.4189 3.1416" />
    <parent
      link="V1pt5_shoulder_roll_link" />
    <child
      link="V1pt5_elbow_link" />
    <axis
      xyz="0 0 1" />
    <limit effort="30" lower="-1.5708" upper="1.5708" velocity="1.0"/>
  </joint>

<link
    name="V1pt5_forearm_link">
    <inertial>
      <origin
        xyz="0.00207964 0.00262015 0.35524838"
        rpy="0 0 0" />
      <mass
        value="0.76927159" />
      <inertia
        ixx="0.00777977"
        ixy="-0.00000407"
        ixz="0.00009563"
        iyy="0.00783744"
        iyz="0.00011094"
        izz="0.00045312" />
    </inertial>
    <visual>
      <origin
        xyz="0 0 0"
        rpy="0 0 0" />
      <geometry>
        <mesh
          filename="package://V1pt5_Arm_URDF/meshes/V1pt5_forearm_link.STL" />
      </geometry>
      <material
        name="">
        <color
          rgba="0.76471 0.64706 1 1" />
      </material>
    </visual>
    <collision>
      <origin
        xyz="0 0 0"
        rpy="0 0 0" />
      <geometry>
        <mesh
          filename="package://V1pt5_Arm_URDF/meshes/V1pt5_forearm_link.STL" />
      </geometry>
    </collision>
  </link>

<joint
    name="V1pt5_forearm_joint"
    type="revolute">
    <origin
      xyz="0.11647 0.43447 0"
      rpy="-1.5708 0 0" />
    <parent
      link="V1pt5_elbow_link" />
    <child
      link="V1pt5_forearm_link" />
    <axis
      xyz="0 0 1" />
    <limit effort="30" lower="-1.5708" upper="1.5708" velocity="1.0"/>
  </joint>

<link
    name="V1pt5_spherical_base_link">
    <inertial>
      <origin
        xyz="0.07922596 0 -0.00707007"
        rpy="0 0 0" />
      <mass
        value="0.600" />
      <inertia
        ixx="0.00032575"
        ixy="0"
        ixz="0.00025917"
        iyy="0.00123265"
        iyz="0"
        izz="0.00110614" />
    </inertial>
    <visual>
      <origin
        xyz="0 0 0"
        rpy="0 0 0" />
      <geometry>
        <mesh
          filename="package://V1pt5_Arm_URDF/meshes/V1pt5_spherical_base_link.STL" />
      </geometry>
      <material
        name="">
        <color
          rgba="0.79216 0.81961 0.93333 1" />
      </material>
    </visual>
    <collision>
      <origin
        xyz="0 0 0"
        rpy="0 0 0" />
      <geometry>
        <mesh
          filename="package://V1pt5_Arm_URDF/meshes/V1pt5_spherical_base_link.STL" />
      </geometry>
    </collision>
  </link>

<joint
    name="V1pt5_spherical_base_joint"
    type="revolute">
    <origin
      xyz="0 0.00202 0"
      rpy="-1.5708 0.9948 -3.1416" />
    <parent
      link="V1pt5_forearm_link" />
    <child
      link="V1pt5_spherical_base_link" />
    <axis
      xyz="0 0 1" />
    <limit effort="30" lower="-1.4820" upper="+2.0087" velocity="1.0"/>
  </joint>

<link
    name="V1pt5_spherical_roll_link">
    <inertial>
      <origin
        xyz="0.04054375 0.01898139 0.00108566"
        rpy="0 0 0" />
      <mass
        value="0.6" />
      <inertia
        ixx="0.00046782"
        ixy="0.00006782"
        ixz="0.00012993"
        iyy="0.00044469"
        iyz="0.00011375"
        izz="0.00045644" />
    </inertial>
    <visual>
      <origin
        xyz="0 0 0"
        rpy="0 0 0" />
      <geometry>
        <mesh
          filename="package://V1pt5_Arm_URDF/meshes/V1pt5_spherical_roll_link.STL" />
      </geometry>
      <material
        name="">
        <color
          rgba="0 0 0 1" />
      </material>
    </visual>
    <collision>
      <origin
        xyz="0 0 0"
        rpy="0 0 0" />
      <geometry>
        <mesh
          filename="package://V1pt5_Arm_URDF/meshes/V1pt5_spherical_roll_link.STL" />
      </geometry>
    </collision>
  </link>

<joint
    name="V1pt5_spherical_roll_joint"
    type="revolute">
    <origin
      xyz="0 -0.19333 0"
      rpy="1.5708 0.1864 0" />
    <parent
      link="V1pt5_spherical_base_link" />
    <child
      link="V1pt5_spherical_roll_link" />
    <axis
      xyz="0 0 1" />
    <limit effort="30" lower="-4.71239" upper="4.71239" velocity="1.0"/>
  </joint>

<link
    name="V1pt5_pitch_a_link">
    <inertial>
      <origin
        xyz="0.05719705 -0.00004469 0.06919435"
        rpy="0 0 0" />
      <mass
        value="0.243" />
      <inertia
        ixx="0.00005379"
        ixy="0.00000004"
        ixz="0"
        iyy="0.00049133"
        iyz="-0.00000007"
        izz="0.00053231" />
    </inertial>
    <visual>
      <origin
        xyz="0 0 0"
        rpy="0 0 0" />
      <geometry>
        <mesh
          filename="package://V1pt5_Arm_URDF/meshes/V1pt5_pitch_a_link.STL" />
      </geometry>
      <material
        name="">
        <color
          rgba="0.5 0 0.5 1" />
      </material>
    </visual>
    <collision>
      <origin
        xyz="0 0 0"
        rpy="0 0 0" />
      <geometry>
        <mesh
          filename="package://V1pt5_Arm_URDF/meshes/V1pt5_pitch_a_link.STL" />
      </geometry>
    </collision>
  </link>

<joint
    name="V1pt5_pitch_a_joint"
    type="revolute">
    <origin
      xyz="0.04753 0 0"
      rpy="1.2021 0.2548 3.0445" />
    <parent
      link="V1pt5_spherical_roll_link" />
    <child
      link="V1pt5_pitch_a_link" />
    <axis
      xyz="0 0 1" />
    <limit effort="30" lower="-1.4198" upper="1.0236" velocity="1.0"/>
  </joint>

  <link
    name="V1pt5_pitch_b_link">
    <inertial>
      <origin
        xyz="0.11423799 -0.00002767 0.0230957192"
        rpy="0 0 0" />
      <mass
        value="0.487" />
      <inertia
        ixx="0.00011057"
        ixy="0.00000046"
        ixz="0.00000147"
        iyy="0.00293978"
        iyz="0"
        izz="0.00302469" />
    </inertial>
    <visual>
      <origin
        xyz="0 0 0"
        rpy="0 0 0" />
      <geometry>
        <mesh
          filename="package://V1pt5_Arm_URDF/meshes/V1pt5_pitch_b_link.STL" />
      </geometry>
      <material
        name="">
        <color
          rgba="0 1 0 1" />
      </material>
    </visual>
    <collision>
      <origin
        xyz="0 0 0"
        rpy="0 0 0" />
      <geometry>
        <mesh
          filename="package://V1pt5_Arm_URDF/meshes/V1pt5_pitch_b_link.STL" />
      </geometry>
    </collision>
  </link>

 <joint
    name="V1_arm1_pitch_b_joint"
    type="revolute">
    <origin
      xyz="0.1143 0 0.0638"
      rpy="0 0 1.6336" />
    <parent
      link="V1pt5_pitch_a_link" />
    <child
      link="V1pt5_pitch_b_link" />
    <axis
      xyz="0 0 1" />
    <limit effort="30" lower="-1.0236" upper="1.4198" velocity="1.0"/>
  </joint>

  <link
    name="V1pt5_pitch_c_link">
    <inertial>
      <origin
        xyz="-0.00636062 -0.09760294 -0.01788714"
        rpy="0 0 0" />
      <mass
        value="0.500" />
      <inertia
        ixx="0.00648952"
        ixy="0.00082224"
        ixz="0.00014234"
        iyy="0.00050852"
        iyz="0.00104333"
        izz="0.00650370" />
    </inertial>
    <visual>
      <origin
        xyz="0 0 0"
        rpy="0 0 0" />
      <geometry>
        <mesh
          filename="package://V1pt5_Arm_URDF/meshes/V1pt5_pitch_c_link.STL" />
      </geometry>
      <material
        name="">
        <color
          rgba="0 0 1 1" />
      </material>
    </visual>
    <collision>
      <origin
        xyz="0 0 0"
        rpy="0 0 0" />
      <geometry>
        <mesh
          filename="package://V1pt5_Arm_URDF/meshes/V1pt5_pitch_c_link.STL" />
      </geometry>
    </collision>
  </link>

  <joint
    name="V1pt5_pitch_c_joint"
    type="revolute">
    <origin
      xyz="0.22860 0 0"
      rpy="0 0 0.2751" />
    <parent
      link="V1pt5_pitch_b_link" />
    <child
      link="V1pt5_pitch_c_link" />
    <axis
      xyz="0 0 1" />
   <limit effort="30" lower="-1.4198" upper="1.0236" velocity="1.0"/>
  </joint>

  <link
    name="V1pt5_tool_translate_link">
    <inertial>
      <origin
        xyz="-0.02077114 -0.00026745 0.27080724"
        rpy="0 0 0" />
      <mass
        value="0.950" />
      <inertia
        ixx="0.00162305"
        ixy="-0.00000190"
        ixz="0.00010383"
        iyy="0.00181538"
        iyz="0.00001572"
        izz="0.00059814" />
    </inertial>
    <visual>
      <origin
        xyz="0 0 0"
        rpy="0 0 0" />
      <geometry>
        <mesh
          filename="package://V1pt5_Arm_URDF/meshes/V1pt5_tool_translate_link.STL" />
      </geometry>
      <material
        name="">
        <color
          rgba="1 0.50196 0.50196 1" />
      </material>
    </visual>
    <collision>
      <origin
        xyz="0 0 0"
        rpy="0 0 0" />
      <geometry>
        <mesh
          filename="package://V1pt5_Arm_URDF/meshes/V1pt5_tool_translate_link.STL" />
      </geometry>
    </collision>
  </link>

 <joint
    name="V1pt5_tool_translate_joint"
    type="prismatic">
    <origin
      xyz="0.03822 0 0"
      rpy="1.7453 0 0" />
    <parent
      link="V1pt5_pitch_c_link" />
    <child
      link="V1pt5_tool_translate_link" />
    <axis
      xyz="0 0 1" />
    <limit effort="30" lower="-.167" upper=".092" velocity="1.0"/>
  </joint>

 <link
    name="V1pt5_tool_rotate_link">
    <inertial>
      <origin
        xyz="0 0 0.20574152"
        rpy="0 0 0" />
      <mass
        value="0.05" />
      <inertia
        ixx="0.00068548"
        ixy="0"
        ixz="0"
        iyy="0.00068548"
        iyz="0"
        izz="0.00000452" />
    </inertial>
    <visual>
      <origin
        xyz="0 0 0"
        rpy="0 0 0" />
      <geometry>
        <mesh
          filename="package://V1pt5_Arm_URDF/meshes/V1pt5_tool_rotate_link.STL" />
      </geometry>
      <material
        name="">
        <color
          rgba="0.79216 0.81961 0.93333 1" />
      </material>
    </visual>
    <collision>
      <origin
        xyz="0 0 0"
        rpy="0 0 0" />
      <geometry>
        <mesh
          filename="package://V1pt5_Arm_URDF/meshes/V1pt5_tool_rotate_link.STL" />
      </geometry>
    </collision>
  </link>

<joint
    name="V1pt5_tool_rotate_joint"
    type="revolute">
    <origin
      xyz="0 0 -0.18910"
      rpy="0 0 0" />
    <parent
      link="V1pt5_tool_translate_link" />
    <child
      link="V1pt5_tool_rotate_link" />
    <axis
      xyz="0 0 1" />
    <limit effort="30" lower="-7.85398" upper="7.85398" velocity="1.0"/>
  </joint>

 <link
    name="V1pt5_proximal_wrist_link">
    <inertial>
      <origin
        xyz="0.00506523 0 0"
        rpy="0 0 0" />
      <mass
        value="0.005" />
      <inertia
        ixx="0.00000004"
        ixy="0"
        ixz="0"
        iyy="0.00000015"
        iyz="0"
        izz="0.00000014" />
    </inertial>
    <visual>
      <origin
        xyz="0 0 0"
        rpy="0 0 0" />
      <geometry>
        <mesh
          filename="package://V1pt5_Arm_URDF/meshes/V1pt5_proximal_wrist_link.STL" />
      </geometry>
      <material
        name="">
        <color
          rgba="0 1 0 1" />
      </material>
    </visual>
    <collision>
      <origin
        xyz="0 0 0"
        rpy="0 0 0" />
      <geometry>
        <mesh
          filename="package://V1pt5_Arm_URDF/meshes/V1pt5_proximal_wrist_link.STL" />
      </geometry>
    </collision>
  </link>

<joint
    name="V1pt5_proximal_wrist_joint"
    type="revolute">
    <origin
      xyz="0 0 0"
      rpy="1.5708 1.5708 0" />
    <parent
      link="V1pt5_tool_rotate_link" />
    <child
      link="V1pt5_proximal_wrist_link" />
    <axis
      xyz="0 0 1" />
    <limit effort="30" lower="-1.5708" upper="1.5708" velocity="1.0"/>
  </joint>

<link
    name="V1pt5_distal_wrist_link">
</link>

<joint
    name="V1pt5_distal_wrist_joint"
    type="revolute">
    <origin
      xyz="0.012333 0 0"
      rpy="-1.5708 0 0" />
    <parent
      link="V1pt5_proximal_wrist_link" />
    <child
      link="V1pt5_distal_wrist_link" />
    <axis
      xyz="0 0 1" />
    <limit effort="30" lower="-1.5708" upper="1.5708" velocity="1.0"/>
</joint>

<link
    name="V1pt5_jaw_a_link">
    <inertial>
      <origin
        xyz="0.0073012 0.00043319 0.0015031"
        rpy="0 0 0" />
      <mass
        value="0.005" />
      <inertia
        ixx="0.00000003"
        ixy="0.00000002"
        ixz="-0.00000004"
        iyy="0.00000037"
        iyz="0"
        izz="0.00000036" />
    </inertial>
    <visual>
      <origin
        xyz="0 0 0"
        rpy="0 0 0" />
      <geometry>
        <mesh
          filename="package://V1pt5_Arm_URDF/meshes/V1pt5_jaw_a_link.STL" />
      </geometry>
      <material
        name="">
        <color
          rgba="0.9098 0.44314 0.031373 1" />
      </material>
    </visual>
    <collision>
      <origin
        xyz="0 0 0"
        rpy="0 0 0" />
      <geometry>
        <mesh
          filename="package://V1pt5_Arm_URDF/meshes/V1pt5_jaw_a_link.STL" />
      </geometry>
    </collision>
</link>

<joint
    name="V1pt5_jaw_a_joint"
    type="revolute">
    <origin
      xyz="0 0 0"
      rpy="0 0 0" />
    <parent
      link="V1pt5_distal_wrist_link" />
    <child
      link="V1pt5_jaw_a_link" />
    <axis
      xyz="0 0 1" />
    <limit effort="30" lower="-1.5708" upper="1.5708" velocity="1.0"/>
  </joint>

<link
    name="V1pt5_jaw_b_link">  
    <inertial>
      <origin
        xyz="0.0073012 0.00043319 0.0015031"
        rpy="0 0 0" />
      <mass
        value="0.005" />
      <inertia
        ixx="0.00000003"
        ixy="0.00000002"
        ixz="-0.00000004"
        iyy="0.00000037"
        iyz="0"
        izz="0.00000036" />
    </inertial>
    <visual>
      <origin
        xyz="0 0 0"
        rpy="0 0 0" />
      <geometry>
        <mesh
          filename="package://V1pt5_Arm_URDF/meshes/V1pt5_jaw_b_link.STL" />
      </geometry>
      <material
        name="">
        <color
          rgba="0.9098 0.44314 0.031373 1" />
      </material>
    </visual>
    <collision>
      <origin
        xyz="0 0 0"
        rpy="0 0 0" />
      <geometry>
        <mesh
          filename="package://V1pt5_Arm_URDF/meshes/V1pt5_jaw_b_link.STL" />
      </geometry>
    </collision>
  </link>

<joint
    name="V1pt5_jaw_b_joint"
    type="revolute">
    <origin
      xyz="0 0 0"
      rpy="0 0 0" />
    <parent
      link="V1pt5_distal_wrist_link" />
    <child
      link="V1pt5_jaw_b_link" />
    <axis
      xyz="0 0 1" />
    <limit effort="30" lower="-1.5708" upper="1.5708" velocity="1.0"/>
  </joint>

/* ATI force-torque sensor: 

<link
    name="V1pt5_ATI_sensor_link">  
    <inertial>
      <origin
        xyz="0.00082860 0 -0.01099715"
        rpy="0 0 0" />
      <mass
        value="0.063" />
      <inertia
        ixx="0.00000474"
        ixy="0.0000000"
        ixz="-0.00000032"
        iyy="0.00000597"
        iyz="-0.00000002"
        izz="0.00000595" />
    </inertial>
    <visual>
      <origin
        xyz="0 0 0"
        rpy="0 0 0" />
      <geometry>
        <mesh
          filename="package://V1pt5_Arm_URDF/meshes/V1pt5_ATI_sensor_link.STL" />
      </geometry>
      <material
        name="">
        <color
          rgba="0.9098 0.44314 0.031373 1" />
      </material>
    </visual>
    <collision>
      <origin
        xyz="0 0 0"
        rpy="0 0 0" />
      <geometry>
        <mesh
          filename="package://V1pt5_Arm_URDF/meshes/V1pt5_ATI_sensor_link.STL" />
      </geometry>
    </collision>
  </link>

<joint
    name="V1pt5_ATI_sensor_joint"
    type="fixed">
    <origin
      xyz="-0.0325471 -0.0043539 -0.0461103"
      rpy="-3.037  0  1.7038" />
    <parent
      link="V1pt5_spherical_roll_link" />
    <child
      link="V1pt5_ATI_sensor_link" />
  </joint>

/* Remote Center of Motion (RCM) link

<link
    name="V1pt5_RCM_link">  
    <inertial>
      <origin
        xyz="0 0 0"
        rpy="0 0 0" />
      <mass
        value="0.001" />
      <inertia
        ixx="0.000004"
        ixy="0.0000000"
        ixz="0.0000000"
        iyy="0.00000004"
        iyz="0.00000000"
        izz="0.00000004" />
    </inertial>
    <visual>
      <origin
        xyz="0 0 0"
        rpy="0 0 0" />
      <geometry>
        <mesh
          filename="package://V1pt5_Arm_URDF/meshes/V1pt5_RCM_link.STL" />
      </geometry>
      <material
        name="">
        <color
          rgba="0.9098 0.44314 0.031373 1" />
      </material>
    </visual>
    <collision>
      <origin
        xyz="0 0 0"
        rpy="0 0 0" />
      <geometry>
        <mesh
          filename="package://V1pt5_Arm_URDF/meshes/V1pt5_RCM_link.STL" />
      </geometry>
    </collision>
  </link>

<joint
    name="V1pt5_RCM_joint"
    type="fixed">
    <origin
      xyz="0.037902 0.10784 0.019015"
      rpy="-1.3844 -0.3566 -0.065734" />
    <parent
      link="V1pt5_pitch_c_link" />
    <child
      link="V1pt5_RCM_link" />
  </joint>

</robot>
